<?xml version='1.0'?>
<sdf version='1.6'>
  <model name='iris_pendulum'>
    <static>false</static>

    <!-- Base Link for Iris -->
    <link name='base_link'>
      <pose>0 0 0 0 0 0</pose>
      <inertial>
        <pose>0 0 0 0 0 0</pose>
        <mass>1.5</mass>
        <inertia>
          <ixx>0.029125</ixx>
          <ixy>0</ixy>
          <ixz>0</ixz>
          <iyy>0.029125</iyy>
          <iyz>0</iyz>
          <izz>0.055225</izz>
        </inertia>
      </inertial>
      <collision name='base_link_inertia_collision'>
        <pose>0 0 0 0 0 0</pose>
        <geometry>
          <box>
            <size>0.47 0.47 0.11</size>
          </box>
        </geometry>
        <surface>
          <contact>
            <ode>
              <min_depth>0.001</min_depth>
              <max_vel>0</max_vel>
            </ode>
          </contact>
          <friction>
            <ode/>
          </friction>
        </surface>
      </collision>
      <visual name='base_link_inertia_visual'>
        <pose>0 0 0 0 0 0</pose>
        <geometry>
          <mesh>
            <scale>1 1 1</scale>
            <uri>model://iris_pendulum/meshes/iris.stl</uri>
          </mesh>
        </geometry>
        <material>
          <script>
            <name>Gazebo/DarkGrey</name>
            <uri>file://media/materials/scripts/gazebo.material</uri>
          </script>
        </material>
      </visual>
      <gravity>1</gravity>
      <velocity_decay/>
    </link>

    <!-- Pendulum -->
    <link name='pendulum'>
        <pose>0 0 -0.5 0 0 0</pose>
        <inertial>
          <mass>0.001</mass>
          <inertia>
            <ixx>0.0008333</ixx>
            <ixy>0</ixy>
            <ixz>0</ixz>
            <iyy>0.0008333</iyy>
            <iyz>0</iyz>
            <izz>0.00005</izz>
          </inertia>
        </inertial>
        <collision name='pendulum_collision'>
          <geometry>
            <cylinder>
              <radius>0.01</radius>
              <length>1.0</length>
            </cylinder>
          </geometry>
          <surface>
            <contact>
              <ode/>
            </contact>
            <friction>
              <ode/>
            </friction>
          </surface>
        </collision>
        <visual name='pendulum_visual'>
          <geometry>
            <cylinder>
              <radius>0.01</radius>
              <length>1.0</length>
            </cylinder>
          </geometry>
          <material>
            <script>
              <name>Gazebo/White</name>
              <uri>file://media/materials/scripts/gazebo.material</uri>
            </script>
          </material>
        </visual>
        <gravity>1</gravity>
    </link>

    <link name='load'>
      <pose>0 0 -1.1 0 0 0</pose>
      <inertial>
        <mass>0.2</mass>
        <inertia>
          <ixx>0.0008</ixx>
          <ixy>0</ixy>
          <ixz>0</ixz>
          <iyy>0.0008</iyy>
          <iyz>0</iyz>
          <izz>0.0008</izz>
        </inertia>
      </inertial>

      <collision name='load_collision'>
        <geometry>
          <sphere>
            <radius>0.1 0.1 0.1</radius>
          </sphere>
        </geometry>
        <surface>
          <contact>
            <ode/>
          </contact>
          <friction>
            <ode/>
          </friction>
        </surface>
      </collision>

      <visual name='load_visual'>
        <geometry>
          <sphere>
            <radius>0.1 0.1 0.1</radius>
          </sphere>
        </geometry>
        <material>
          <script>
            <name>Gazebo/Red</name>
            <uri>file://media/materials/scripts/gazebo.material</uri>
          </script>
        </material>
      </visual>
      <gravity>1</gravity>
    </link>

    <joint name='load_joint' type='universal'>
      <pose>0 0 0.1 0 0 0</pose>
      <child>load</child>
      <parent>pendulum</parent>
    </joint>

    <joint name='pendulum_joint' type='universal'>
      <pose>0 0 0.5 0 0 0</pose>
      <axis>
        <xyz>1 0 0</xyz>
      </axis>
      <axis2>
        <xyz>0 1 0</xyz>
      </axis2>
      <child>pendulum</child>
      <parent>base_link</parent>
    </joint>


  <!-- Pendulum Plugin -->
  <plugin name="MissionPlugin" filename="libMission_plugin.so" />
  </model>
</sdf>
